<mujoco model="One Car Scene">
  <compiler autolimits="true"/>

  <option viscosity="0.5"/>

  <default>
    <joint damping=".03" actuatorfrcrange="-0.5 0.5"/>
    <default class="wheel">
      <geom type="cylinder" size=".03 .01" rgba=".5 .5 1 1"/>
    </default>
    <default class="decor">
      <site type="box" rgba=".5 1 .5 1"/>
    </default>
  </default>

  <asset>
    <!-- Общие ассеты -->
    <texture type="skybox" builtin="gradient" rgb1="0.3 0.5 0.7" rgb2="0 0 0" width="512" height="3072"/>
    <texture type="2d" name="groundplane" builtin="checker" mark="edge" rgb1="0.2 0.3 0.4" rgb2="0.1 0.2 0.3" markrgb="0.8 0.8 0.8" width="300" height="300"/>
    <material name="groundplane" texture="groundplane" texuniform="true" texrepeat="5 5" reflectance="0.2"/>

    <!-- Ассеты для Car 1 -->
    <texture name="car1_qr" type="2d" file="qr_codes/qr_1.png"/>
    <material name="car1_qr_material" texture="car1_qr" />
    <mesh name="car1_chasis" scale=".01 .006 .0015" vertex=" 9 2 0 -10 10 10 9 -2 0 10 3 -10 10 -3 -10 -8 10 -10 -10 -10 10 -8 -10 -10 -5 0 20"/>

    <texture name="car2_qr" type="2d" file="qr_codes/qr_2.png"/>
    <material name="car2_qr_material" texture="car2_qr" />
    <mesh name="car2_chasis" scale=".01 .006 .0015" vertex=" 9 2 0 -10 10 10 9 -2 0 10 3 -10 10 -3 -10 -8 10 -10 -10 -10 10 -8 -10 -10 -5 0 20"/>
  </asset>

  <worldbody>
    <light pos="0 0 1"/>
    <light pos="0 -0.2 1" dir="0 0.2 -0.8" directional="true"/>
    <geom name="floor" size="3 3 .01" type="plane" material="groundplane"/>

    <!-- ================== CAR 1 ================== -->
    <body name="car1" pos="1.0 0.0 .03">
      <camera name="car1_front_cam" mode="fixed" pos="0.1 0 0.0" euler="0 -90 270" fovy="45"/>
      <freejoint/>
      <light name="car1_top_light" pos="0 0 2" mode="trackcom" diffuse=".4 .4 .4"/>
      <geom name="car1_chasis" type="mesh" mesh="car1_chasis"/>
      <geom name="car1_qr_code_geom" type="box" size=".03 .03 .001" pos="-.1 0 .01" material="car1_qr_material" euler="90 90 0"/>
      <geom name="car1_front_wheel" pos=".08 0 -.015" type="sphere" size=".015" condim="1" priority="1"/>
      <light name="car1_front_light" pos=".1 0 .05" dir="2 0 -1" diffuse="1 1 1"/>
      <body name="car1_left_wheel" pos="-.07 .06 0" zaxis="0 1 0">
        <joint name="car1_left"/>
        <geom class="wheel"/>
        <site class="decor" size=".006 .025 .012"/>
        <site class="decor" size=".025 .006 .012"/>
      </body>
      <body name="car1_right_wheel" pos="-.07 -.06 0" zaxis="0 1 0">
        <joint name="car1_right"/>
        <geom class="wheel"/>
        <site class="decor" size=".006 .025 .012"/>
        <site class="decor" size=".025 .006 .012"/>
      </body>
      <site name="car1_imu" pos="0 0 0.02" size="0.005" rgba="1 1 0 1"/>
      <site name="car1_sensor_front" pos="0.09 0 0.02" size="0.005" rgba="1 0 0 1"/>
      <site name="car1_sensor_left"  pos="0 0.07 0.02" size="0.005" rgba="0 1 0 1"/>
      <site name="car1_sensor_right" pos="0 -0.07 0.02" size="0.005" rgba="0 0 1 1"/>
    </body>
    <!-- ================== CAR 2 ==================
    <body name="car2" pos="0.8775825618903728  0.2397127693021015 .03">
    -->
    <body name="car2" pos="0.8775825618903728  0.25 .03">
      <camera name="car2_front_cam" mode="fixed" pos="0.1 0 0.0" euler="0 -90 270" fovy="45"/>
      <freejoint/>
      <light name="car2_top_light" pos="0 0 2" mode="trackcom" diffuse=".4 .4 .4"/>
      <geom name="car2_chasis" type="mesh" mesh="car2_chasis"/>
      <geom name="car2_qr_code_geom" type="box" size=".03 .03 .001" pos="-.1 0 .01" material="car2_qr_material" euler="90 90 0"/>
      <geom name="car2_front_wheel" pos=".08 0 -.015" type="sphere" size=".015" condim="1" priority="1"/>
      <light name="car2_front_light" pos=".1 0 .02" dir="2 0 -1" diffuse="1 1 1"/>
      <body name="car2_left_wheel" pos="-.07 .06 0" zaxis="0 1 0">
        <joint name="car2_left"/>
        <geom class="wheel"/>
        <site class="decor" size=".006 .025 .012"/>
        <site class="decor" size=".025 .006 .012"/>
      </body>
      <body name="car2_right_wheel" pos="-.07 -.06 0" zaxis="0 1 0">
        <joint name="car2_right"/>
        <geom class="wheel"/>
        <site class="decor" size=".006 .025 .012"/>
        <site class="decor" size=".025 .006 .012"/>
      </body>
      <site name="car2_imu" pos="0 0 0.02" size="0.005" rgba="1 1 0 1"/>
      <site name="car2_sensor_front" pos="0.09 0 0.02" size="0.005" rgba="1 0 0 1"/>
      <site name="car2_sensor_left"  pos="0 0.07 0.02" size="0.005" rgba="0 1 0 1"/>
      <site name="car2_sensor_right" pos="0 -0.07 0.02" size="0.005" rgba="0 0 1 1"/>
    </body>
  </worldbody>

  <tendon>
    <fixed name="car1_forward">
      <joint joint="car1_left" coef=".5"/>
      <joint joint="car1_right" coef=".5"/>
    </fixed>
    <fixed name="car1_turn">
      <joint joint="car1_left" coef="-.5"/>
      <joint joint="car1_right" coef=".5"/>
    </fixed>
    <fixed name="car2_forward">
      <joint joint="car2_left" coef=".5"/>
      <joint joint="car2_right" coef=".5"/>
    </fixed>
    <fixed name="car2_turn">
      <joint joint="car2_left" coef="-.5"/>
      <joint joint="car2_right" coef=".5"/>
    </fixed>
  </tendon>

  <actuator>
    <motor name="car1_forward" tendon="car1_forward" ctrlrange="-1 1"/>
    <motor name="car1_turn" tendon="car1_turn" ctrlrange="-1 1"/>
    <motor name="car2_forward" tendon="car2_forward" ctrlrange="-1 1"/>
    <motor name="car2_turn" tendon="car2_turn" ctrlrange="-1 1"/>
  </actuator>

  <sensor>
    <!-- Сенсоры Car 1 -->
    <jointactuatorfrc name="car1_right_frc" joint="car1_right"/>
    <jointactuatorfrc name="car1_left_frc" joint="car1_left"/>
    <gyro name="car1_gyro" site="car1_imu"/>
    <accelerometer name="car1_accel" site="car1_imu"/>
    <!-- Сенсоры Car 2 -->
    <jointactuatorfrc name="car2_right_frc" joint="car2_right"/>
    <jointactuatorfrc name="car2_left_frc" joint="car2_left"/>
    <gyro name="car2_gyro" site="car2_imu"/>
    <accelerometer name="car2_accel" site="car2_imu"/>
  </sensor>
</mujoco>
